![[Pasted image 20250903135500.png]]

12

代码执行过程分析：  
1. 首先执行try块中的代码 100/0,这会抛出算术异常(ArithmeticException)  
2. 进入catch块,输出1  
3. catch块中抛出新的RuntimeException异常  
4. 无论是否发生异常,finally块都会执行,输出2  
5. 由于catch块中抛出了未被捕获的RuntimeException,程序在执行完finally块后会终止  
6. System.out.print(3)这行代码不会被执行到  
  
因此最终输出为"12"，D选项正确。